Workbook

Sheet PI Furnizor
A1: PRODUSE COMANDATE (din PI) - O LINIE = UN PRODUS DINTR-O COMANDA
A3: Adauga produse noi pe prima linie libera de la capat (zona galbena). Alege ID-ul comenzii din lista (comenzile se creeaza in foaia 'Comenzi', unde sunt data, cursul si transportul fiecareia). Preturile unitare sunt in moneda comenzii. Pentru transport pe CBM completeaza FIE 'Volum/buc (CBM)' direct, FIE dimensiunile cartonului + cate bucati intra intr-un carton (volumul/buc se calculeaza singur). Greutatea e per bucata. Tot ce adaugi aici apare automat in 'Calculator Cost per Bucata' si 'Comparatie Piata RO' (capacitate: 500 linii).
A5: DATE PRODUS - completeaza (galben) | N5: CALCUL AUTOMAT
A6: ID comanda | B6: Item Number | C6: Descriere | D6: Cantitate (buc) | E6: Pret unitar (USD) | F6: Greutate neta /buc (kg) | G6: Buc / carton | H6: Lungime carton (cm) | I6: Latime carton (cm) | J6: Inaltime carton (cm) | K6: Volum /buc (CBM) - manual, optional | L6: Pret gasit in Romania (RON) - optional | M6: Observatii | N6: Valoare totala marfa (USD) | O6: Greutate totala (kg) | P6: Volum /buc folosit (CBM) | Q6: Volum total (CBM)
A7: C001 | B7: 8821-DS | C7: Christmas flower | D7: 1 | E7: 6.15 | F7: 0.55 | L7: 130 | N7: =IF($D7="","",$D7*N($E7)) -> 6.15 | O7: =IF($D7="","",$D7*N($F7)) -> 0.55 | P7: =IF($D7="","",IF(N($K7)>0,$K7,IF(AND(N($G7)>0,N($H7)>0,N($I7)>0,N($J7)>0),$H7*$I7*$J7/1000000/$G7,0))) -> 0 | Q7: =IF($D7="","",$D7*$P7) -> 0
A8: C001 | B8: 11153-DS | C8: Garland | D8: 1 | E8: 5.51 | F8: 0.43 | L8: 200 | N8: =IF($D8="","",$D8*N($E8)) -> 5.51 | O8: =IF($D8="","",$D8*N($F8)) -> 0.43 | P8: =IF($D8="","",IF(N($K8)>0,$K8,IF(AND(N($G8)>0,N($H8)>0,N($I8)>0,N($J8)>0),$H8*$I8*$J8/1000000/$G8,0))) -> 0 | Q8: =IF($D8="","",$D8*$P8) -> 0
A9: C001 | B9: C0230 | C9: EC-Fairy Land-Castle | D9: 1 | E9: 4.23 | F9: 0.8 | L9: 132 | N9: =IF($D9="","",$D9*N($E9)) -> 4.23 | O9: =IF($D9="","",$D9*N($F9)) -> 0.8 | P9: =IF($D9="","",IF(N($K9)>0,$K9,IF(AND(N($G9)>0,N($H9)>0,N($I9)>0,N($J9)>0),$H9*$I9*$J9/1000000/$G9,0))) -> 0 | Q9: =IF($D9="","",$D9*$P9) -> 0
A10: C001 | B10: 11152-DS | C10: Train | D10: 1 | E10: 7.87 | F10: 0.63 | L10: 220 | N10: =IF($D10="","",$D10*N($E10)) -> 7.87 | O10: =IF($D10="","",$D10*N($F10)) -> 0.63 | P10: =IF($D10="","",IF(N($K10)>0,$K10,IF(AND(N($G10)>0,N($H10)>0,N($I10)>0,N($J10)>0),$H10*$I10*$J10/1000000/$G10,0))) -> 0 | Q10: =IF($D10="","",$D10*$P10) -> 0
A11: C001 | B11: 11823-DS | C11: Christmas series | D11: 1 | E11: 7.71 | F11: 1.3 | L11: 300 | N11: =IF($D11="","",$D11*N($E11)) -> 7.71 | O11: =IF($D11="","",$D11*N($F11)) -> 1.3 | P11: =IF($D11="","",IF(N($K11)>0,$K11,IF(AND(N($G11)>0,N($H11)>0,N($I11)>0,N($J11)>0),$H11*$I11*$J11/1000000/$G11,0))) -> 0 | Q11: =IF($D11="","",$D11*$P11) -> 0
A12: C002 | B12: 13116 | C12: Plum Blossom | D12: 3 | E12: 3.69 | F12: 0.6 | L12: 180 | N12: =IF($D12="","",$D12*N($E12)) -> 11.07 | O12: =IF($D12="","",$D12*N($F12)) -> 1.8 | P12: =IF($D12="","",IF(N($K12)>0,$K12,IF(AND(N($G12)>0,N($H12)>0,N($I12)>0,N($J12)>0),$H12*$I12*$J12/1000000/$G12,0))) -> 0 | Q12: =IF($D12="","",$D12*$P12) -> 0
A13: C001 | B13: C0864 | C13: EC-003 Type Aircraft carrier | D13: 1 | E13: 8.92 | F13: 1.23 | L13: 520 | N13: =IF($D13="","",$D13*N($E13)) -> 8.92 | O13: =IF($D13="","",$D13*N($F13)) -> 1.23 | P13: =IF($D13="","",IF(N($K13)>0,$K13,IF(AND(N($G13)>0,N($H13)>0,N($I13)>0,N($J13)>0),$H13*$I13*$J13/1000000/$G13,0))) -> 0 | Q13: =IF($D13="","",$D13*$P13) -> 0
N14: =IF($D14="","",$D14*N($E14)) | O14: =IF($D14="","",$D14*N($F14)) | P14: =IF($D14="","",IF(N($K14)>0,$K14,IF(AND(N($G14)>0,N($H14)>0,N($I14)>0,N($J14)>0),$H14*$I14*$J14/1000000/$G14,0))) | Q14: =IF($D14="","",$D14*$P14)
N15: =IF($D15="","",$D15*N($E15)) | O15: =IF($D15="","",$D15*N($F15)) | P15: =IF($D15="","",IF(N($K15)>0,$K15,IF(AND(N($G15)>0,N($H15)>0,N($I15)>0,N($J15)>0),$H15*$I15*$J15/1000000/$G15,0))) | Q15: =IF($D15="","",$D15*$P15)
N16: =IF($D16="","",$D16*N($E16)) | O16: =IF($D16="","",$D16*N($F16)) | P16: =IF($D16="","",IF(N($K16)>0,$K16,IF(AND(N($G16)>0,N($H16)>0,N($I16)>0,N($J16)>0),$H16*$I16*$J16/1000000/$G16,0))) | Q16: =IF($D16="","",$D16*$P16)
N17: =IF($D17="","",$D17*N($E17)) | O17: =IF($D17="","",$D17*N($F17)) | P17: =IF($D17="","",IF(N($K17)>0,$K17,IF(AND(N($G17)>0,N($H17)>0,N($I17)>0,N($J17)>0),$H17*$I17*$J17/1000000/$G17,0))) | Q17: =IF($D17="","",$D17*$P17)
N18: =IF($D18="","",$D18*N($E18)) | O18: =IF($D18="","",$D18*N($F18)) | P18: =IF($D18="","",IF(N($K18)>0,$K18,IF(AND(N($G18)>0,N($H18)>0,N($I18)>0,N($J18)>0),$H18*$I18*$J18/1000000/$G18,0))) | Q18: =IF($D18="","",$D18*$P18)
N19: =IF($D19="","",$D19*N($E19)) | O19: =IF($D19="","",$D19*N($F19)) | P19: =IF($D19="","",IF(N($K19)>0,$K19,IF(AND(N($G19)>0,N($H19)>0,N($I19)>0,N($J19)>0),$H19*$I19*$J19/1000000/$G19,0))) | Q19: =IF($D19="","",$D19*$P19)
N20: =IF($D20="","",$D20*N($E20)) | O20: =IF($D20="","",$D20*N($F20)) | P20: =IF($D20="","",IF(N($K20)>0,$K20,IF(AND(N($G20)>0,N($H20)>0,N($I20)>0,N($J20)>0),$H20*$I20*$J20/1000000/$G20,0))) | Q20: =IF($D20="","",$D20*$P20)
N21: =IF($D21="","",$D21*N($E21)) | O21: =IF($D21="","",$D21*N($F21)) | P21: =IF($D21="","",IF(N($K21)>0,$K21,IF(AND(N($G21)>0,N($H21)>0,N($I21)>0,N($J21)>0),$H21*$I21*$J21/1000000/$G21,0))) | Q21: =IF($D21="","",$D21*$P21)
N22: =IF($D22="","",$D22*N($E22)) | O22: =IF($D22="","",$D22*N($F22)) | P22: =IF($D22="","",IF(N($K22)>0,$K22,IF(AND(N($G22)>0,N($H22)>0,N($I22)>0,N($J22)>0),$H22*$I22*$J22/1000000/$G22,0))) | Q22: =IF($D22="","",$D22*$P22)
N23: =IF($D23="","",$D23*N($E23)) | O23: =IF($D23="","",$D23*N($F23)) | P23: =IF($D23="","",IF(N($K23)>0,$K23,IF(AND(N($G23)>0,N($H23)>0,N($I23)>0,N($J23)>0),$H23*$I23*$J23/1000000/$G23,0))) | Q23: =IF($D23="","",$D23*$P23)
N24: =IF($D24="","",$D24*N($E24)) | O24: =IF($D24="","",$D24*N($F24)) | P24: =IF($D24="","",IF(N($K24)>0,$K24,IF(AND(N($G24)>0,N($H24)>0,N($I24)>0,N($J24)>0),$H24*$I24*$J24/1000000/$G24,0))) | Q24: =IF($D24="","",$D24*$P24)
N25: =IF($D25="","",$D25*N($E25)) | O25: =IF($D25="","",$D25*N($F25)) | P25: =IF($D25="","",IF(N($K25)>0,$K25,IF(AND(N($G25)>0,N($H25)>0,N($I25)>0,N($J25)>0),$H25*$I25*$J25/1000000/$G25,0))) | Q25: =IF($D25="","",$D25*$P25)
... N506: =IF($D506="","",$D506*N($E506)) | O506: =IF($D506="","",$D506*N($F506)) | P506: =IF($D506="","",IF(N($K506)>0,$K506,IF(AND(N($G506)>0,N($H506)>0,N($I506)>0,N($J506)>0),$H506*$I506*$J506/1000000/$G506,0))) | Q506: =IF($D506="","",$D506*$P506)

Sheet Comenzi
A1: COMENZI / PROFORMA INVOICE-URI - O LINIE = O COMANDA (data, curs, transport proprii)
A3: Cota TVA import implicita (daca lasi gol in coloana V) | D3: 0.21 | F3: Cum folosesti: pentru fiecare comanda noua adaugi O LINIE (galben) pe prima linie libera de mai jos si ii dai un ID unic (ex. C002). In foaia 'PI Furnizor' scrii produsele cu acel ID. Fiecare comanda are propria data, propriul curs USD/EUR si propriul tarif de transport (pe kg, pe CBM sau total fix). Coloanele gri se calculeaza singure. Nota DDP: desi Incoterm-ul din PI poate fi DDP, pentru colete aeriene taxele/TVA se platesc de regula la sosire - calculatorul presupune ca TU platesti taxele la intrarea in tara. Taxe 2026 colete sub 150 EUR (Reg. UE 2026/382 - 3 EUR/categorie de produs, tranzitoriu; taxa logistica RO 25 lei/colet): confirma valorile curente cu curierul/brokerul.
A4: Taxa vamala standard implicita (daca lasi gol in coloana U) | D4: 0
A5: Divizor greutate volumetrica aerian (cm3 / kg) | D5: 6000
A6: Firma platitoare de TVA? (Da/Nu) - schimba baza comparatiei in foaia Comparatie | D6: Nu
A7: DATE COMANDA - completeaza (galben) | X7: CALCUL AUTOMAT (nu modifica)
A8: ID comanda (unic) | B8: Data comanda | C8: Furnizor | D8: Nr. PI / Invoice | E8: Incoterm | F8: Tip transport | G8: Moneda marfa (din PI) | H8: Curs USD -> RON (la data comenzii) | I8: Curs EUR -> RON (la data comenzii) | J8: Moneda transport | K8: Baza tarif transport | L8: Tarif transport (moneda transport) | M8: Minim taxabil (kg sau CBM) | N8: Greutate volumetrica? (Da/Nu) | O8: Asigurare + alte costuri transport (moneda transport) | P8: Nr. categorii distincte produse | Q8: Taxa forfetara UE (EUR/categorie) | R8: Nr. colete | S8: Taxa logistica RO (lei/colet) | T8: Comision broker / transport intern (RON) | U8: Taxa vamala standard (%) | V8: Cota TVA import | W8: Metoda alocare transport + taxe fixe | X8: Nr. linii produse | Y8: Cantitate totala (buc) | Z8: Greutate reala totala (kg) | AA8: Volum total (CBM) | AB8: Valoare marfa (USD) | AC8: Valoare marfa (RON) | AD8: Greutate volumetrica (kg) | AE8: Cantitate taxabila (kg / CBM / 1) | AF8: Transport + asig. (USD) | AG8: Transport + asig. TOTAL (RON) | AH8: Transport RON / kg real | AI8: Transport RON / CBM | AJ8: Taxa vamala forfetara TOTAL (RON) | AK8: Taxa logistica RO TOTAL (RON) | AL8: Metoda alocare aleasa | AM8: Metoda alocare efectiva | AN8: Total cheie alocare | AO8: COST TOTAL fara TVA (RON) | AP8: TVA import TOTAL (RON) | AQ8: COST TOTAL cu TVA (RON) | AR8: COST TOTAL cu TVA (EUR) | AS8: COST TOTAL cu TVA (USD) | AT8: Avertismente
A9: C001 | B9: 46260 | C9: Guangdong Woma Animation Toys Co.,Ltd | D9: WM20260826-2 | E9: DDP | F9: Aerian | G9: USD | H9: 4.7364 | I9: 5.3344 | J9: USD | K9: Total fix | L9: 68.08 | N9: Nu | O9: 0 | P9: 6 | Q9: 0 | R9: 1 | S9: 0 | T9: 0 | W9: Greutate | X9: =IF($A9="","",COUNTIFS('PI Furnizor'!$A$7:$A$506,$A9,'PI Furnizor'!$D$7:$D$506,">0")) -> 6 | Y9: =IF($A9="","",SUMIFS('PI Furnizor'!$D$7:$D$506,'PI Furnizor'!$A$7:$A$506,$A9)) -> 6 | Z9: =IF($A9="","",SUMIFS('PI Furnizor'!$O$7:$O$506,'PI Furnizor'!$A$7:$A$506,$A9)) -> 4.94 | AA9: =IF($A9="","",SUMIFS('PI Furnizor'!$Q$7:$Q$506,'PI Furnizor'!$A$7:$A$506,$A9)) -> 0 | AB9: =IF($A9="","",SUMIFS('PI Furnizor'!$N$7:$N$506,'PI Furnizor'!$A$7:$A$506,$A9)) -> 40.39 | AC9: =IF($A9="","",$AB9*IF($G9="USD",N($H9),IF($G9="EUR",N($I9),1))) -> 191.3032 | AD9: =IF($A9="","",IF($N9="Da",$AA9*1000000/$D$5,0)) -> 0 | AE9: =IF($A9="","",IF($K9="CBM",MAX($AA9,N($M9)),IF($K9="kg",MAX($Z9,IF($N9="Da",$AD9,0),N($M9)),1))) -> 1 | AF9: =IF($A9="","",IF($K9="Total fix",N($L9),N($L9)*$AE9)+N($O9)) -> 68.08 | AG9: =IF($A9="","",$AF9*IF($J9="USD",N($H9),IF($J9="EUR",N($I9),1))) -> 322.45411 | AH9: =IF($A9="","",IF($Z9>0,$AG9/$Z9,"")) -> 65.274112 | AI9: =IF($A9="","",IF($AA9>0,$AG9/$AA9,"")) | AJ9: =IF($A9="","",N($P9)*N($Q9)*N($I9)) -> 0 | AK9: =IF($A9="","",N($R9)*N($S9)) -> 0 | AL9: =IF($A9="","",IF(OR($W9="",$W9="Automat"),IF($K9="CBM","Volum (CBM)","Greutate"),$W9)) -> Greutate | AM9: =IF($A9="","",IF($AL9="Greutate",IF($Z9>0,"Greutate","Egal pe bucata"),IF($AL9="Volum (CBM)",IF($AA9>0,"Volum (CBM)","Egal pe bucata"),IF($AL9="Valoare marfa",IF($AB9>0,"Valoare marfa","Egal pe bucata"),"Egal pe bucata")))) -> Greutate | AN9: =IF($A9="","",IF($AM9="Greutate",$Z9,IF($AM9="Volum (CBM)",$AA9,IF($AM9="Valoare marfa",$AB9,$Y9)))) -> 4.94 | AO9: =IF($A9="","",SUMIFS('Calculator Cost per Bucata'!$V$10:$V$509,'Calculator Cost per Bucata'!$A$10:$A$509,$A9)) -> 513.75731 | AP9: =IF($A9="","",$AQ9-$AO9) -> 107.88903 | AQ9: =IF($A9="","",SUMIFS('Calculator Cost per Bucata'!$W$10:$W$509,'Calculator Cost per Bucata'!$A$10:$A$509,$A9)) -> 621.64634 | AR9: =IF($A9="","",IF(N($I9)>0,$AQ9/$I9,"")) -> 116.53538 | AS9: =IF($A9="","",IF(N($H9)>0,$AQ9/$H9,"")) -> 131.2487 | AT9: =IF($A9="","",IF((N($H9)<=0)+(N($I9)<=0)+($X9=0)+(OR($G9="",$J9="",$K9=""))+(AND($K9="CBM",$AA9=0))+(AND($K9="kg",$Z9=0))+($AL9<>$AM9)=0,"OK",IF(N($H9)<=0,"Lipseste cursul USD. ","")&IF(N($I9)<=0,"Lipseste cursul EUR. ","")&IF($X9=0,"Nicio linie de produs in 'PI Furnizor'. ","")&IF(OR($G9="",$J9="",$K9=""),"Lipseste moneda marfa / moneda transport / baza tarif. ","")&IF(AND($K9="CBM",$AA9=0),"Tarif pe CBM dar lipsesc dimensiunile/volumul. ","")&IF(AND($K9="kg",$Z9=0),"Tarif pe kg dar lipsesc greutatile. ","")&IF($AL9<>$AM9,"Cheia de alocare lipseste - costurile se impart egal pe bucata. ",""))) -> OK
A10: C002 | B10: 08.10.2026 | C10: Guangzhou Longcheng Ceramics Co., Limited | D10: WM20260826-3 | E10: DDP | F10: Aerian | G10: USD | H10: 4.7801 | I10: 5.3501 | J10: USD | K10: Total fix | L10: 44.05 | N10: Nu | O10: 0 | P10: 1 | Q10: 0 | R10: 1 | W10: Egal pe bucata | X10: =IF($A10="","",COUNTIFS('PI Furnizor'!$A$7:$A$506,$A10,'PI Furnizor'!$D$7:$D$506,">0")) -> 1 | Y10: =IF($A10="","",SUMIFS('PI Furnizor'!$D$7:$D$506,'PI Furnizor'!$A$7:$A$506,$A10)) -> 3 | Z10: =IF($A10="","",SUMIFS('PI Furnizor'!$O$7:$O$506,'PI Furnizor'!$A$7:$A$506,$A10)) -> 1.8 | AA10: =IF($A10="","",SUMIFS('PI Furnizor'!$Q$7:$Q$506,'PI Furnizor'!$A$7:$A$506,$A10)) -> 0 | AB10: =IF($A10="","",SUMIFS('PI Furnizor'!$N$7:$N$506,'PI Furnizor'!$A$7:$A$506,$A10)) -> 11.07 | AC10: =IF($A10="","",$AB10*IF($G10="USD",N($H10),IF($G10="EUR",N($I10),1))) -> 52.915707 | AD10: =IF($A10="","",IF($N10="Da",$AA10*1000000/$D$5,0)) -> 0 | AE10: =IF($A10="","",IF($K10="CBM",MAX($AA10,N($M10)),IF($K10="kg",MAX($Z10,IF($N10="Da",$AD10,0),N($M10)),1))) -> 1 | AF10: =IF($A10="","",IF($K10="Total fix",N($L10),N($L10)*$AE10)+N($O10)) -> 44.05 | AG10: =IF($A10="","",$AF10*IF($J10="USD",N($H10),IF($J10="EUR",N($I10),1))) -> 210.5634 | AH10: =IF($A10="","",IF($Z10>0,$AG10/$Z10,"")) -> 116.97967 | AI10: =IF($A10="","",IF($AA10>0,$AG10/$AA10,"")) | AJ10: =IF($A10="","",N($P10)*N($Q10)*N($I10)) -> 0 | AK10: =IF($A10="","",N($R10)*N($S10)) -> 0 | AL10: =IF($A10="","",IF(OR($W10="",$W10="Automat"),IF($K10="CBM","Volum (CBM)","Greutate"),$W10)) -> Egal pe bucata | AM10: =IF($A10="","",IF($AL10="Greutate",IF($Z10>0,"Greutate","Egal pe bucata"),IF($AL10="Volum (CBM)",IF($AA10>0,"Volum (CBM)","Egal pe bucata"),IF($AL10="Valoare marfa",IF($AB10>0,"Valoare marfa","Egal pe bucata"),"Egal pe bucata")))) -> Egal pe bucata | AN10: =IF($A10="","",IF($AM10="Greutate",$Z10,IF($AM10="Volum (CBM)",$AA10,IF($AM10="Valoare marfa",$AB10,$Y10)))) -> 3 | AO10: =IF($A10="","",SUMIFS('Calculator Cost per Bucata'!$V$10:$V$509,'Calculator Cost per Bucata'!$A$10:$A$509,$A10)) -> 263.47911 | AP10: =IF($A10="","",$AQ10-$AO10) -> 55.330614 | AQ10: =IF($A10="","",SUMIFS('Calculator Cost per Bucata'!$W$10:$W$509,'Calculator Cost per Bucata'!$A$10:$A$509,$A10)) -> 318.80973 | AR10: =IF($A10="","",IF(N($I10)>0,$AQ10/$I10,"")) -> 59.589489 | AS10: =IF($A10="","",IF(N($H10)>0,$AQ10/$H10,"")) -> 66.6952 | AT10: =IF($A10="","",IF((N($H10)<=0)+(N($I10)<=0)+($X10=0)+(OR($G10="",$J10="",$K10=""))+(AND($K10="CBM",$AA10=0))+(AND($K10="kg",$Z10=0))+($AL10<>$AM10)=0,"OK",IF(N($H10)<=0,"Lipseste cursul USD. ","")&IF(N($I10)<=0,"Lipseste cursul EUR. ","")&IF($X10=0,"Nicio linie de produs in 'PI Furnizor'. ","")&IF(OR($G10="",$J10="",$K10=""),"Lipseste moneda marfa / moneda transport / baza tarif. ","")&IF(AND($K10="CBM",$AA10=0),"Tarif pe CBM dar lipsesc dimensiunile/volumul. ","")&IF(AND($K10="kg",$Z10=0),"Tarif pe kg dar lipsesc greutatile. ","")&IF($AL10<>$AM10,"Cheia de alocare lipseste - costurile se impart egal pe bucata. ",""))) -> OK
X11: =IF($A11="","",COUNTIFS('PI Furnizor'!$A$7:$A$506,$A11,'PI Furnizor'!$D$7:$D$506,">0")) | Y11: =IF($A11="","",SUMIFS('PI Furnizor'!$D$7:$D$506,'PI Furnizor'!$A$7:$A$506,$A11)) | Z11: =IF($A11="","",SUMIFS('PI Furnizor'!$O$7:$O$506,'PI Furnizor'!$A$7:$A$506,$A11)) | AA11: =IF($A11="","",SUMIFS('PI Furnizor'!$Q$7:$Q$506,'PI Furnizor'!$A$7:$A$506,$A11)) | AB11: =IF($A11="","",SUMIFS('PI Furnizor'!$N$7:$N$506,'PI Furnizor'!$A$7:$A$506,$A11)) | AC11: =IF($A11="","",$AB11*IF($G11="USD",N($H11),IF($G11="EUR",N($I11),1))) | AD11: =IF($A11="","",IF($N11="Da",$AA11*1000000/$D$5,0)) | AE11: =IF($A11="","",IF($K11="CBM",MAX($AA11,N($M11)),IF($K11="kg",MAX($Z11,IF($N11="Da",$AD11,0),N($M11)),1))) | AF11: =IF($A11="","",IF($K11="Total fix",N($L11),N($L11)*$AE11)+N($O11)) | AG11: =IF($A11="","",$AF11*IF($J11="USD",N($H11),IF($J11="EUR",N($I11),1))) | AH11: =IF($A11="","",IF($Z11>0,$AG11/$Z11,"")) | AI11: =IF($A11="","",IF($AA11>0,$AG11/$AA11,"")) | AJ11: =IF($A11="","",N($P11)*N($Q11)*N($I11)) | AK11: =IF($A11="","",N($R11)*N($S11)) | AL11: =IF($A11="","",IF(OR($W11="",$W11="Automat"),IF($K11="CBM","Volum (CBM)","Greutate"),$W11)) | AM11: =IF($A11="","",IF($AL11="Greutate",IF($Z11>0,"Greutate","Egal pe bucata"),IF($AL11="Volum (CBM)",IF($AA11>0,"Volum (CBM)","Egal pe bucata"),IF($AL11="Valoare marfa",IF($AB11>0,"Valoare marfa","Egal pe bucata"),"Egal pe bucata")))) | AN11: =IF($A11="","",IF($AM11="Greutate",$Z11,IF($AM11="Volum (CBM)",$AA11,IF($AM11="Valoare marfa",$AB11,$Y11)))) | AO11: =IF($A11="","",SUMIFS('Calculator Cost per Bucata'!$V$10:$V$509,'Calculator Cost per Bucata'!$A$10:$A$509,$A11)) | AP11: =IF($A11="","",$AQ11-$AO11) | AQ11: =IF($A11="","",SUMIFS('Calculator Cost per Bucata'!$W$10:$W$509,'Calculator Cost per Bucata'!$A$10:$A$509,$A11)) | AR11: =IF($A11="","",IF(N($I11)>0,$AQ11/$I11,"")) | AS11: =IF($A11="","",IF(N($H11)>0,$AQ11/$H11,"")) | AT11: =IF($A11="","",IF((N($H11)<=0)+(N($I11)<=0)+($X11=0)+(OR($G11="",$J11="",$K11=""))+(AND($K11="CBM",$AA11=0))+(AND($K11="kg",$Z11=0))+($AL11<>$AM11)=0,"OK",IF(N($H11)<=0,"Lipseste cursul USD. ","")&IF(N($I11)<=0,"Lipseste cursul EUR. ","")&IF($X11=0,"Nicio linie de produs in 'PI Furnizor'. ","")&IF(OR($G11="",$J11="",$K11=""),"Lipseste moneda marfa / moneda transport / baza tarif. ","")&IF(AND($K11="CBM",$AA11=0),"Tarif pe CBM dar lipsesc dimensiunile/volumul. ","")&IF(AND($K11="kg",$Z11=0),"Tarif pe kg dar lipsesc greutatile. ","")&IF($AL11<>$AM11,"Cheia de alocare lipseste - costurile se impart egal pe bucata. ","")))
X12: =IF($A12="","",COUNTIFS('PI Furnizor'!$A$7:$A$506,$A12,'PI Furnizor'!$D$7:$D$506,">0")) | Y12: =IF($A12="","",SUMIFS('PI Furnizor'!$D$7:$D$506,'PI Furnizor'!$A$7:$A$506,$A12)) | Z12: =IF($A12="","",SUMIFS('PI Furnizor'!$O$7:$O$506,'PI Furnizor'!$A$7:$A$506,$A12)) | AA12: =IF($A12="","",SUMIFS('PI Furnizor'!$Q$7:$Q$506,'PI Furnizor'!$A$7:$A$506,$A12)) | AB12: =IF($A12="","",SUMIFS('PI Furnizor'!$N$7:$N$506,'PI Furnizor'!$A$7:$A$506,$A12)) | AC12: =IF($A12="","",$AB12*IF($G12="USD",N($H12),IF($G12="EUR",N($I12),1))) | AD12: =IF($A12="","",IF($N12="Da",$AA12*1000000/$D$5,0)) | AE12: =IF($A12="","",IF($K12="CBM",MAX($AA12,N($M12)),IF($K12="kg",MAX($Z12,IF($N12="Da",$AD12,0),N($M12)),1))) | AF12: =IF($A12="","",IF($K12="Total fix",N($L12),N($L12)*$AE12)+N($O12)) | AG12: =IF($A12="","",$AF12*IF($J12="USD",N($H12),IF($J12="EUR",N($I12),1))) | AH12: =IF($A12="","",IF($Z12>0,$AG12/$Z12,"")) | AI12: =IF($A12="","",IF($AA12>0,$AG12/$AA12,"")) | AJ12: =IF($A12="","",N($P12)*N($Q12)*N($I12)) | AK12: =IF($A12="","",N($R12)*N($S12)) | AL12: =IF($A12="","",IF(OR($W12="",$W12="Automat"),IF($K12="CBM","Volum (CBM)","Greutate"),$W12)) | AM12: =IF($A12="","",IF($AL12="Greutate",IF($Z12>0,"Greutate","Egal pe bucata"),IF($AL12="Volum (CBM)",IF($AA12>0,"Volum (CBM)","Egal pe bucata"),IF($AL12="Valoare marfa",IF($AB12>0,"Valoare marfa","Egal pe bucata"),"Egal pe bucata")))) | AN12: =IF($A12="","",IF($AM12="Greutate",$Z12,IF($AM12="Volum (CBM)",$AA12,IF($AM12="Valoare marfa",$AB12,$Y12)))) | AO12: =IF($A12="","",SUMIFS('Calculator Cost per Bucata'!$V$10:$V$509,'Calculator Cost per Bucata'!$A$10:$A$509,$A12)) | AP12: =IF($A12="","",$AQ12-$AO12) | AQ12: =IF($A12="","",SUMIFS('Calculator Cost per Bucata'!$W$10:$W$509,'Calculator Cost per Bucata'!$A$10:$A$509,$A12)) | AR12: =IF($A12="","",IF(N($I12)>0,$AQ12/$I12,"")) | AS12: =IF($A12="","",IF(N($H12)>0,$AQ12/$H12,"")) | AT12: =IF($A12="","",IF((N($H12)<=0)+(N($I12)<=0)+($X12=0)+(OR($G12="",$J12="",$K12=""))+(AND($K12="CBM",$AA12=0))+(AND($K12="kg",$Z12=0))+($AL12<>$AM12)=0,"OK",IF(N($H12)<=0,"Lipseste cursul USD. ","")&IF(N($I12)<=0,"Lipseste cursul EUR. ","")&IF($X12=0,"Nicio linie de produs in 'PI Furnizor'. ","")&IF(OR($G12="",$J12="",$K12=""),"Lipseste moneda marfa / moneda transport / baza tarif. ","")&IF(AND($K12="CBM",$AA12=0),"Tarif pe CBM dar lipsesc dimensiunile/volumul. ","")&IF(AND($K12="kg",$Z12=0),"Tarif pe kg dar lipsesc greutatile. ","")&IF($AL12<>$AM12,"Cheia de alocare lipseste - costurile se impart egal pe bucata. ","")))
X13: =IF($A13="","",COUNTIFS('PI Furnizor'!$A$7:$A$506,$A13,'PI Furnizor'!$D$7:$D$506,">0")) | Y13: =IF($A13="","",SUMIFS('PI Furnizor'!$D$7:$D$506,'PI Furnizor'!$A$7:$A$506,$A13)) | Z13: =IF($A13="","",SUMIFS('PI Furnizor'!$O$7:$O$506,'PI Furnizor'!$A$7:$A$506,$A13)) | AA13: =IF($A13="","",SUMIFS('PI Furnizor'!$Q$7:$Q$506,'PI Furnizor'!$A$7:$A$506,$A13)) | AB13: =IF($A13="","",SUMIFS('PI Furnizor'!$N$7:$N$506,'PI Furnizor'!$A$7:$A$506,$A13)) | AC13: =IF($A13="","",$AB13*IF($G13="USD",N($H13),IF($G13="EUR",N($I13),1))) | AD13: =IF($A13="","",IF($N13="Da",$AA13*1000000/$D$5,0)) | AE13: =IF($A13="","",IF($K13="CBM",MAX($AA13,N($M13)),IF($K13="kg",MAX($Z13,IF($N13="Da",$AD13,0),N($M13)),1))) | AF13: =IF($A13="","",IF($K13="Total fix",N($L13),N($L13)*$AE13)+N($O13)) | AG13: =IF($A13="","",$AF13*IF($J13="USD",N($H13),IF($J13="EUR",N($I13),1))) | AH13: =IF($A13="","",IF($Z13>0,$AG13/$Z13,"")) | AI13: =IF($A13="","",IF($AA13>0,$AG13/$AA13,"")) | AJ13: =IF($A13="","",N($P13)*N($Q13)*N($I13)) | AK13: =IF($A13="","",N($R13)*N($S13)) | AL13: =IF($A13="","",IF(OR($W13="",$W13="Automat"),IF($K13="CBM","Volum (CBM)","Greutate"),$W13)) | AM13: =IF($A13="","",IF($AL13="Greutate",IF($Z13>0,"Greutate","Egal pe bucata"),IF($AL13="Volum (CBM)",IF($AA13>0,"Volum (CBM)","Egal pe bucata"),IF($AL13="Valoare marfa",IF($AB13>0,"Valoare marfa","Egal pe bucata"),"Egal pe bucata")))) | AN13: =IF($A13="","",IF($AM13="Greutate",$Z13,IF($AM13="Volum (CBM)",$AA13,IF($AM13="Valoare marfa",$AB13,$Y13)))) | AO13: =IF($A13="","",SUMIFS('Calculator Cost per Bucata'!$V$10:$V$509,'Calculator Cost per Bucata'!$A$10:$A$509,$A13)) | AP13: =IF($A13="","",$AQ13-$AO13) | AQ13: =IF($A13="","",SUMIFS('Calculator Cost per Bucata'!$W$10:$W$509,'Calculator Cost per Bucata'!$A$10:$A$509,$A13)) | AR13: =IF($A13="","",IF(N($I13)>0,$AQ13/$I13,"")) | AS13: =IF($A13="","",IF(N($H13)>0,$AQ13/$H13,"")) | AT13: =IF($A13="","",IF((N($H13)<=0)+(N($I13)<=0)+($X13=0)+(OR($G13="",$J13="",$K13=""))+(AND($K13="CBM",$AA13=0))+(AND($K13="kg",$Z13=0))+($AL13<>$AM13)=0,"OK",IF(N($H13)<=0,"Lipseste cursul USD. ","")&IF(N($I13)<=0,"Lipseste cursul EUR. ","")&IF($X13=0,"Nicio linie de produs in 'PI Furnizor'. ","")&IF(OR($G13="",$J13="",$K13=""),"Lipseste moneda marfa / moneda transport / baza tarif. ","")&IF(AND($K13="CBM",$AA13=0),"Tarif pe CBM dar lipsesc dimensiunile/volumul. ","")&IF(AND($K13="kg",$Z13=0),"Tarif pe kg dar lipsesc greutatile. ","")&IF($AL13<>$AM13,"Cheia de alocare lipseste - costurile se impart egal pe bucata. ","")))
X14: =IF($A14="","",COUNTIFS('PI Furnizor'!$A$7:$A$506,$A14,'PI Furnizor'!$D$7:$D$506,">0")) | Y14: =IF($A14="","",SUMIFS('PI Furnizor'!$D$7:$D$506,'PI Furnizor'!$A$7:$A$506,$A14)) | Z14: =IF($A14="","",SUMIFS('PI Furnizor'!$O$7:$O$506,'PI Furnizor'!$A$7:$A$506,$A14)) | AA14: =IF($A14="","",SUMIFS('PI Furnizor'!$Q$7:$Q$506,'PI Furnizor'!$A$7:$A$506,$A14)) | AB14: =IF($A14="","",SUMIFS('PI Furnizor'!$N$7:$N$506,'PI Furnizor'!$A$7:$A$506,$A14)) | AC14: =IF($A14="","",$AB14*IF($G14="USD",N($H14),IF($G14="EUR",N($I14),1))) | AD14: =IF($A14="","",IF($N14="Da",$AA14*1000000/$D$5,0)) | AE14: =IF($A14="","",IF($K14="CBM",MAX($AA14,N($M14)),IF($K14="kg",MAX($Z14,IF($N14="Da",$AD14,0),N($M14)),1))) | AF14: =IF($A14="","",IF($K14="Total fix",N($L14),N($L14)*$AE14)+N($O14)) | AG14: =IF($A14="","",$AF14*IF($J14="USD",N($H14),IF($J14="EUR",N($I14),1))) | AH14: =IF($A14="","",IF($Z14>0,$AG14/$Z14,"")) | AI14: =IF($A14="","",IF($AA14>0,$AG14/$AA14,"")) | AJ14: =IF($A14="","",N($P14)*N($Q14)*N($I14)) | AK14: =IF($A14="","",N($R14)*N($S14)) | AL14: =IF($A14="","",IF(OR($W14="",$W14="Automat"),IF($K14="CBM","Volum (CBM)","Greutate"),$W14)) | AM14: =IF($A14="","",IF($AL14="Greutate",IF($Z14>0,"Greutate","Egal pe bucata"),IF($AL14="Volum (CBM)",IF($AA14>0,"Volum (CBM)","Egal pe bucata"),IF($AL14="Valoare marfa",IF($AB14>0,"Valoare marfa","Egal pe bucata"),"Egal pe bucata")))) | AN14: =IF($A14="","",IF($AM14="Greutate",$Z14,IF($AM14="Volum (CBM)",$AA14,IF($AM14="Valoare marfa",$AB14,$Y14)))) | AO14: =IF($A14="","",SUMIFS('Calculator Cost per Bucata'!$V$10:$V$509,'Calculator Cost per Bucata'!$A$10:$A$509,$A14)) | AP14: =IF($A14="","",$AQ14-$AO14) | AQ14: =IF($A14="","",SUMIFS('Calculator Cost per Bucata'!$W$10:$W$509,'Calculator Cost per Bucata'!$A$10:$A$509,$A14)) | AR14: =IF($A14="","",IF(N($I14)>0,$AQ14/$I14,"")) | AS14: =IF($A14="","",IF(N($H14)>0,$AQ14/$H14,"")) | AT14: =IF($A14="","",IF((N($H14)<=0)+(N($I14)<=0)+($X14=0)+(OR($G14="",$J14="",$K14=""))+(AND($K14="CBM",$AA14=0))+(AND($K14="kg",$Z14=0))+($AL14<>$AM14)=0,"OK",IF(N($H14)<=0,"Lipseste cursul USD. ","")&IF(N($I14)<=0,"Lipseste cursul EUR. ","")&IF($X14=0,"Nicio linie de produs in 'PI Furnizor'. ","")&IF(OR($G14="",$J14="",$K14=""),"Lipseste moneda marfa / moneda transport / baza tarif. ","")&IF(AND($K14="CBM",$AA14=0),"Tarif pe CBM dar lipsesc dimensiunile/volumul. ","")&IF(AND($K14="kg",$Z14=0),"Tarif pe kg dar lipsesc greutatile. ","")&IF($AL14<>$AM14,"Cheia de alocare lipseste - costurile se impart egal pe bucata. ","")))
X15: =IF($A15="","",COUNTIFS('PI Furnizor'!$A$7:$A$506,$A15,'PI Furnizor'!$D$7:$D$506,">0")) | Y15: =IF($A15="","",SUMIFS('PI Furnizor'!$D$7:$D$506,'PI Furnizor'!$A$7:$A$506,$A15)) | Z15: =IF($A15="","",SUMIFS('PI Furnizor'!$O$7:$O$506,'PI Furnizor'!$A$7:$A$506,$A15)) | AA15: =IF($A15="","",SUMIFS('PI Furnizor'!$Q$7:$Q$506,'PI Furnizor'!$A$7:$A$506,$A15)) | AB15: =IF($A15="","",SUMIFS('PI Furnizor'!$N$7:$N$506,'PI Furnizor'!$A$7:$A$506,$A15)) | AC15: =IF($A15="","",$AB15*IF($G15="USD",N($H15),IF($G15="EUR",N($I15),1))) | AD15: =IF($A15="","",IF($N15="Da",$AA15*1000000/$D$5,0)) | AE15: =IF($A15="","",IF($K15="CBM",MAX($AA15,N($M15)),IF($K15="kg",MAX($Z15,IF($N15="Da",$AD15,0),N($M15)),1))) | AF15: =IF($A15="","",IF($K15="Total fix",N($L15),N($L15)*$AE15)+N($O15)) | AG15: =IF($A15="","",$AF15*IF($J15="USD",N($H15),IF($J15="EUR",N($I15),1))) | AH15: =IF($A15="","",IF($Z15>0,$AG15/$Z15,"")) | AI15: =IF($A15="","",IF($AA15>0,$AG15/$AA15,"")) | AJ15: =IF($A15="","",N($P15)*N($Q15)*N($I15)) | AK15: =IF($A15="","",N($R15)*N($S15)) | AL15: =IF($A15="","",IF(OR($W15="",$W15="Automat"),IF($K15="CBM","Volum (CBM)","Greutate"),$W15)) | AM15: =IF($A15="","",IF($AL15="Greutate",IF($Z15>0,"Greutate","Egal pe bucata"),IF($AL15="Volum (CBM)",IF($AA15>0,"Volum (CBM)","Egal pe bucata"),IF($AL15="Valoare marfa",IF($AB15>0,"Valoare marfa","Egal pe bucata"),"Egal pe bucata")))) | AN15: =IF($A15="","",IF($AM15="Greutate",$Z15,IF($AM15="Volum (CBM)",$AA15,IF($AM15="Valoare marfa",$AB15,$Y15)))) | AO15: =IF($A15="","",SUMIFS('Calculator Cost per Bucata'!$V$10:$V$509,'Calculator Cost per Bucata'!$A$10:$A$509,$A15)) | AP15: =IF($A15="","",$AQ15-$AO15) | AQ15: =IF($A15="","",SUMIFS('Calculator Cost per Bucata'!$W$10:$W$509,'Calculator Cost per Bucata'!$A$10:$A$509,$A15)) | AR15: =IF($A15="","",IF(N($I15)>0,$AQ15/$I15,"")) | AS15: =IF($A15="","",IF(N($H15)>0,$AQ15/$H15,"")) | AT15: =IF($A15="","",IF((N($H15)<=0)+(N($I15)<=0)+($X15=0)+(OR($G15="",$J15="",$K15=""))+(AND($K15="CBM",$AA15=0))+(AND($K15="kg",$Z15=0))+($AL15<>$AM15)=0,"OK",IF(N($H15)<=0,"Lipseste cursul USD. ","")&IF(N($I15)<=0,"Lipseste cursul EUR. ","")&IF($X15=0,"Nicio linie de produs in 'PI Furnizor'. ","")&IF(OR($G15="",$J15="",$K15=""),"Lipseste moneda marfa / moneda transport / baza tarif. ","")&IF(AND($K15="CBM",$AA15=0),"Tarif pe CBM dar lipsesc dimensiunile/volumul. ","")&IF(AND($K15="kg",$Z15=0),"Tarif pe kg dar lipsesc greutatile. ","")&IF($AL15<>$AM15,"Cheia de alocare lipseste - costurile se impart egal pe bucata. ","")))
X16: =IF($A16="","",COUNTIFS('PI Furnizor'!$A$7:$A$506,$A16,'PI Furnizor'!$D$7:$D$506,">0")) | Y16: =IF($A16="","",SUMIFS('PI Furnizor'!$D$7:$D$506,'PI Furnizor'!$A$7:$A$506,$A16)) | Z16: =IF($A16="","",SUMIFS('PI Furnizor'!$O$7:$O$506,'PI Furnizor'!$A$7:$A$506,$A16)) | AA16: =IF($A16="","",SUMIFS('PI Furnizor'!$Q$7:$Q$506,'PI Furnizor'!$A$7:$A$506,$A16)) | AB16: =IF($A16="","",SUMIFS('PI Furnizor'!$N$7:$N$506,'PI Furnizor'!$A$7:$A$506,$A16)) | AC16: =IF($A16="","",$AB16*IF($G16="USD",N($H16),IF($G16="EUR",N($I16),1))) | AD16: =IF($A16="","",IF($N16="Da",$AA16*1000000/$D$5,0)) | AE16: =IF($A16="","",IF($K16="CBM",MAX($AA16,N($M16)),IF($K16="kg",MAX($Z16,IF($N16="Da",$AD16,0),N($M16)),1))) | AF16: =IF($A16="","",IF($K16="Total fix",N($L16),N($L16)*$AE16)+N($O16)) | AG16: =IF($A16="","",$AF16*IF($J16="USD",N($H16),IF($J16="EUR",N($I16),1))) | AH16: =IF($A16="","",IF($Z16>0,$AG16/$Z16,"")) | AI16: =IF($A16="","",IF($AA16>0,$AG16/$AA16,"")) | AJ16: =IF($A16="","",N($P16)*N($Q16)*N($I16)) | AK16: =IF($A16="","",N($R16)*N($S16)) | AL16: =IF($A16="","",IF(OR($W16="",$W16="Automat"),IF($K16="CBM","Volum (CBM)","Greutate"),$W16)) | AM16: =IF($A16="","",IF($AL16="Greutate",IF($Z16>0,"Greutate","Egal pe bucata"),IF($AL16="Volum (CBM)",IF($AA16>0,"Volum (CBM)","Egal pe bucata"),IF($AL16="Valoare marfa",IF($AB16>0,"Valoare marfa","Egal pe bucata"),"Egal pe bucata")))) | AN16: =IF($A16="","",IF($AM16="Greutate",$Z16,IF($AM16="Volum (CBM)",$AA16,IF($AM16="Valoare marfa",$AB16,$Y16)))) | AO16: =IF($A16="","",SUMIFS('Calculator Cost per Bucata'!$V$10:$V$509,'Calculator Cost per Bucata'!$A$10:$A$509,$A16)) | AP16: =IF($A16="","",$AQ16-$AO16) | AQ16: =IF($A16="","",SUMIFS('Calculator Cost per Bucata'!$W$10:$W$509,'Calculator Cost per Bucata'!$A$10:$A$509,$A16)) | AR16: =IF($A16="","",IF(N($I16)>0,$AQ16/$I16,"")) | AS16: =IF($A16="","",IF(N($H16)>0,$AQ16/$H16,"")) | AT16: =IF($A16="","",IF((N($H16)<=0)+(N($I16)<=0)+($X16=0)+(OR($G16="",$J16="",$K16=""))+(AND($K16="CBM",$AA16=0))+(AND($K16="kg",$Z16=0))+($AL16<>$AM16)=0,"OK",IF(N($H16)<=0,"Lipseste cursul USD. ","")&IF(N($I16)<=0,"Lipseste cursul EUR. ","")&IF($X16=0,"Nicio linie de produs in 'PI Furnizor'. ","")&IF(OR($G16="",$J16="",$K16=""),"Lipseste moneda marfa / moneda transport / baza tarif. ","")&IF(AND($K16="CBM",$AA16=0),"Tarif pe CBM dar lipsesc dimensiunile/volumul. ","")&IF(AND($K16="kg",$Z16=0),"Tarif pe kg dar lipsesc greutatile. ","")&IF($AL16<>$AM16,"Cheia de alocare lipseste - costurile se impart egal pe bucata. ","")))
X17: =IF($A17="","",COUNTIFS('PI Furnizor'!$A$7:$A$506,$A17,'PI Furnizor'!$D$7:$D$506,">0")) | Y17: =IF($A17="","",SUMIFS('PI Furnizor'!$D$7:$D$506,'PI Furnizor'!$A$7:$A$506,$A17)) | Z17: =IF($A17="","",SUMIFS('PI Furnizor'!$O$7:$O$506,'PI Furnizor'!$A$7:$A$506,$A17)) | AA17: =IF($A17="","",SUMIFS('PI Furnizor'!$Q$7:$Q$506,'PI Furnizor'!$A$7:$A$506,$A17)) | AB17: =IF($A17="","",SUMIFS('PI Furnizor'!$N$7:$N$506,'PI Furnizor'!$A$7:$A$506,$A17)) | AC17: =IF($A17="","",$AB17*IF($G17="USD",N($H17),IF($G17="EUR",N($I17),1))) | AD17: =IF($A17="","",IF($N17="Da",$AA17*1000000/$D$5,0)) | AE17: =IF($A17="","",IF($K17="CBM",MAX($AA17,N($M17)),IF($K17="kg",MAX($Z17,IF($N17="Da",$AD17,0),N($M17)),1))) | AF17: =IF($A17="","",IF($K17="Total fix",N($L17),N($L17)*$AE17)+N($O17)) | AG17: =IF($A17="","",$AF17*IF($J17="USD",N($H17),IF($J17="EUR",N($I17),1))) | AH17: =IF($A17="","",IF($Z17>0,$AG17/$Z17,"")) | AI17: =IF($A17="","",IF($AA17>0,$AG17/$AA17,"")) | AJ17: =IF($A17="","",N($P17)*N($Q17)*N($I17)) | AK17: =IF($A17="","",N($R17)*N($S17)) | AL17: =IF($A17="","",IF(OR($W17="",$W17="Automat"),IF($K17="CBM","Volum (CBM)","Greutate"),$W17)) | AM17: =IF($A17="","",IF($AL17="Greutate",IF($Z17>0,"Greutate","Egal pe bucata"),IF($AL17="Volum (CBM)",IF($AA17>0,"Volum (CBM)","Egal pe bucata"),IF($AL17="Valoare marfa",IF($AB17>0,"Valoare marfa","Egal pe bucata"),"Egal pe bucata")))) | AN17: =IF($A17="","",IF($AM17="Greutate",$Z17,IF($AM17="Volum (CBM)",$AA17,IF($AM17="Valoare marfa",$AB17,$Y17)))) | AO17: =IF($A17="","",SUMIFS('Calculator Cost per Bucata'!$V$10:$V$509,'Calculator Cost per Bucata'!$A$10:$A$509,$A17)) | AP17: =IF($A17="","",$AQ17-$AO17) | AQ17: =IF($A17="","",SUMIFS('Calculator Cost per Bucata'!$W$10:$W$509,'Calculator Cost per Bucata'!$A$10:$A$509,$A17)) | AR17: =IF($A17="","",IF(N($I17)>0,$AQ17/$I17,"")) | AS17: =IF($A17="","",IF(N($H17)>0,$AQ17/$H17,"")) | AT17: =IF($A17="","",IF((N($H17)<=0)+(N($I17)<=0)+($X17=0)+(OR($G17="",$J17="",$K17=""))+(AND($K17="CBM",$AA17=0))+(AND($K17="kg",$Z17=0))+($AL17<>$AM17)=0,"OK",IF(N($H17)<=0,"Lipseste cursul USD. ","")&IF(N($I17)<=0,"Lipseste cursul EUR. ","")&IF($X17=0,"Nicio linie de produs in 'PI Furnizor'. ","")&IF(OR($G17="",$J17="",$K17=""),"Lipseste moneda marfa / moneda transport / baza tarif. ","")&IF(AND($K17="CBM",$AA17=0),"Tarif pe CBM dar lipsesc dimensiunile/volumul. ","")&IF(AND($K17="kg",$Z17=0),"Tarif pe kg dar lipsesc greutatile. ","")&IF($AL17<>$AM17,"Cheia de alocare lipseste - costurile se impart egal pe bucata. ","")))
X18: =IF($A18="","",COUNTIFS('PI Furnizor'!$A$7:$A$506,$A18,'PI Furnizor'!$D$7:$D$506,">0")) | Y18: =IF($A18="","",SUMIFS('PI Furnizor'!$D$7:$D$506,'PI Furnizor'!$A$7:$A$506,$A18)) | Z18: =IF($A18="","",SUMIFS('PI Furnizor'!$O$7:$O$506,'PI Furnizor'!$A$7:$A$506,$A18)) | AA18: =IF($A18="","",SUMIFS('PI Furnizor'!$Q$7:$Q$506,'PI Furnizor'!$A$7:$A$506,$A18)) | AB18: =IF($A18="","",SUMIFS('PI Furnizor'!$N$7:$N$506,'PI Furnizor'!$A$7:$A$506,$A18)) | AC18: =IF($A18="","",$AB18*IF($G18="USD",N($H18),IF($G18="EUR",N($I18),1))) | AD18: =IF($A18="","",IF($N18="Da",$AA18*1000000/$D$5,0)) | AE18: =IF($A18="","",IF($K18="CBM",MAX($AA18,N($M18)),IF($K18="kg",MAX($Z18,IF($N18="Da",$AD18,0),N($M18)),1))) | AF18: =IF($A18="","",IF($K18="Total fix",N($L18),N($L18)*$AE18)+N($O18)) | AG18: =IF($A18="","",$AF18*IF($J18="USD",N($H18),IF($J18="EUR",N($I18),1))) | AH18: =IF($A18="","",IF($Z18>0,$AG18/$Z18,"")) | AI18: =IF($A18="","",IF($AA18>0,$AG18/$AA18,"")) | AJ18: =IF($A18="","",N($P18)*N($Q18)*N($I18)) | AK18: =IF($A18="","",N($R18)*N($S18)) | AL18: =IF($A18="","",IF(OR($W18="",$W18="Automat"),IF($K18="CBM","Volum (CBM)","Greutate"),$W18)) | AM18: =IF($A18="","",IF($AL18="Greutate",IF($Z18>0,"Greutate","Egal pe bucata"),IF($AL18="Volum (CBM)",IF($AA18>0,"Volum (CBM)","Egal pe bucata"),IF($AL18="Valoare marfa",IF($AB18>0,"Valoare marfa","Egal pe bucata"),"Egal pe bucata")))) | AN18: =IF($A18="","",IF($AM18="Greutate",$Z18,IF($AM18="Volum (CBM)",$AA18,IF($AM18="Valoare marfa",$AB18,$Y18)))) | AO18: =IF($A18="","",SUMIFS('Calculator Cost per Bucata'!$V$10:$V$509,'Calculator Cost per Bucata'!$A$10:$A$509,$A18)) | AP18: =IF($A18="","",$AQ18-$AO18) | AQ18: =IF($A18="","",SUMIFS('Calculator Cost per Bucata'!$W$10:$W$509,'Calculator Cost per Bucata'!$A$10:$A$509,$A18)) | AR18: =IF($A18="","",IF(N($I18)>0,$AQ18/$I18,"")) | AS18: =IF($A18="","",IF(N($H18)>0,$AQ18/$H18,"")) | AT18: =IF($A18="","",IF((N($H18)<=0)+(N($I18)<=0)+($X18=0)+(OR($G18="",$J18="",$K18=""))+(AND($K18="CBM",$AA18=0))+(AND($K18="kg",$Z18=0))+($AL18<>$AM18)=0,"OK",IF(N($H18)<=0,"Lipseste cursul USD. ","")&IF(N($I18)<=0,"Lipseste cursul EUR. ","")&IF($X18=0,"Nicio linie de produs in 'PI Furnizor'. ","")&IF(OR($G18="",$J18="",$K18=""),"Lipseste moneda marfa / moneda transport / baza tarif. ","")&IF(AND($K18="CBM",$AA18=0),"Tarif pe CBM dar lipsesc dimensiunile/volumul. ","")&IF(AND($K18="kg",$Z18=0),"Tarif pe kg dar lipsesc greutatile. ","")&IF($AL18<>$AM18,"Cheia de alocare lipseste - costurile se impart egal pe bucata. ","")))
X19: =IF($A19="","",COUNTIFS('PI Furnizor'!$A$7:$A$506,$A19,'PI Furnizor'!$D$7:$D$506,">0")) | Y19: =IF($A19="","",SUMIFS('PI Furnizor'!$D$7:$D$506,'PI Furnizor'!$A$7:$A$506,$A19)) | Z19: =IF($A19="","",SUMIFS('PI Furnizor'!$O$7:$O$506,'PI Furnizor'!$A$7:$A$506,$A19)) | AA19: =IF($A19="","",SUMIFS('PI Furnizor'!$Q$7:$Q$506,'PI Furnizor'!$A$7:$A$506,$A19)) | AB19: =IF($A19="","",SUMIFS('PI Furnizor'!$N$7:$N$506,'PI Furnizor'!$A$7:$A$506,$A19)) | AC19: =IF($A19="","",$AB19*IF($G19="USD",N($H19),IF($G19="EUR",N($I19),1))) | AD19: =IF($A19="","",IF($N19="Da",$AA19*1000000/$D$5,0)) | AE19: =IF($A19="","",IF($K19="CBM",MAX($AA19,N($M19)),IF($K19="kg",MAX($Z19,IF($N19="Da",$AD19,0),N($M19)),1))) | AF19: =IF($A19="","",IF($K19="Total fix",N($L19),N($L19)*$AE19)+N($O19)) | AG19: =IF($A19="","",$AF19*IF($J19="USD",N($H19),IF($J19="EUR",N($I19),1))) | AH19: =IF($A19="","",IF($Z19>0,$AG19/$Z19,"")) | AI19: =IF($A19="","",IF($AA19>0,$AG19/$AA19,"")) | AJ19: =IF($A19="","",N($P19)*N($Q19)*N($I19)) | AK19: =IF($A19="","",N($R19)*N($S19)) | AL19: =IF($A19="","",IF(OR($W19="",$W19="Automat"),IF($K19="CBM","Volum (CBM)","Greutate"),$W19)) | AM19: =IF($A19="","",IF($AL19="Greutate",IF($Z19>0,"Greutate","Egal pe bucata"),IF($AL19="Volum (CBM)",IF($AA19>0,"Volum (CBM)","Egal pe bucata"),IF($AL19="Valoare marfa",IF($AB19>0,"Valoare marfa","Egal pe bucata"),"Egal pe bucata")))) | AN19: =IF($A19="","",IF($AM19="Greutate",$Z19,IF($AM19="Volum (CBM)",$AA19,IF($AM19="Valoare marfa",$AB19,$Y19)))) | AO19: =IF($A19="","",SUMIFS('Calculator Cost per Bucata'!$V$10:$V$509,'Calculator Cost per Bucata'!$A$10:$A$509,$A19)) | AP19: =IF($A19="","",$AQ19-$AO19) | AQ19: =IF($A19="","",SUMIFS('Calculator Cost per Bucata'!$W$10:$W$509,'Calculator Cost per Bucata'!$A$10:$A$509,$A19)) | AR19: =IF($A19="","",IF(N($I19)>0,$AQ19/$I19,"")) | AS19: =IF($A19="","",IF(N($H19)>0,$AQ19/$H19,"")) | AT19: =IF($A19="","",IF((N($H19)<=0)+(N($I19)<=0)+($X19=0)+(OR($G19="",$J19="",$K19=""))+(AND($K19="CBM",$AA19=0))+(AND($K19="kg",$Z19=0))+($AL19<>$AM19)=0,"OK",IF(N($H19)<=0,"Lipseste cursul USD. ","")&IF(N($I19)<=0,"Lipseste cursul EUR. ","")&IF($X19=0,"Nicio linie de produs in 'PI Furnizor'. ","")&IF(OR($G19="",$J19="",$K19=""),"Lipseste moneda marfa / moneda transport / baza tarif. ","")&IF(AND($K19="CBM",$AA19=0),"Tarif pe CBM dar lipsesc dimensiunile/volumul. ","")&IF(AND($K19="kg",$Z19=0),"Tarif pe kg dar lipsesc greutatile. ","")&IF($AL19<>$AM19,"Cheia de alocare lipseste - costurile se impart egal pe bucata. ","")))
X20: =IF($A20="","",COUNTIFS('PI Furnizor'!$A$7:$A$506,$A20,'PI Furnizor'!$D$7:$D$506,">0")) | Y20: =IF($A20="","",SUMIFS('PI Furnizor'!$D$7:$D$506,'PI Furnizor'!$A$7:$A$506,$A20)) | Z20: =IF($A20="","",SUMIFS('PI Furnizor'!$O$7:$O$506,'PI Furnizor'!$A$7:$A$506,$A20)) | AA20: =IF($A20="","",SUMIFS('PI Furnizor'!$Q$7:$Q$506,'PI Furnizor'!$A$7:$A$506,$A20)) | AB20: =IF($A20="","",SUMIFS('PI Furnizor'!$N$7:$N$506,'PI Furnizor'!$A$7:$A$506,$A20)) | AC20: =IF($A20="","",$AB20*IF($G20="USD",N($H20),IF($G20="EUR",N($I20),1))) | AD20: =IF($A20="","",IF($N20="Da",$AA20*1000000/$D$5,0)) | AE20: =IF($A20="","",IF($K20="CBM",MAX($AA20,N($M20)),IF($K20="kg",MAX($Z20,IF($N20="Da",$AD20,0),N($M20)),1))) | AF20: =IF($A20="","",IF($K20="Total fix",N($L20),N($L20)*$AE20)+N($O20)) | AG20: =IF($A20="","",$AF20*IF($J20="USD",N($H20),IF($J20="EUR",N($I20),1))) | AH20: =IF($A20="","",IF($Z20>0,$AG20/$Z20,"")) | AI20: =IF($A20="","",IF($AA20>0,$AG20/$AA20,"")) | AJ20: =IF($A20="","",N($P20)*N($Q20)*N($I20)) | AK20: =IF($A20="","",N($R20)*N($S20)) | AL20: =IF($A20="","",IF(OR($W20="",$W20="Automat"),IF($K20="CBM","Volum (CBM)","Greutate"),$W20)) | AM20: =IF($A20="","",IF($AL20="Greutate",IF($Z20>0,"Greutate","Egal pe bucata"),IF($AL20="Volum (CBM)",IF($AA20>0,"Volum (CBM)","Egal pe bucata"),IF($AL20="Valoare marfa",IF($AB20>0,"Valoare marfa","Egal pe bucata"),"Egal pe bucata")))) | AN20: =IF($A20="","",IF($AM20="Greutate",$Z20,IF($AM20="Volum (CBM)",$AA20,IF($AM20="Valoare marfa",$AB20,$Y20)))) | AO20: =IF($A20="","",SUMIFS('Calculator Cost per Bucata'!$V$10:$V$509,'Calculator Cost per Bucata'!$A$10:$A$509,$A20)) | AP20: =IF($A20="","",$AQ20-$AO20) | AQ20: =IF($A20="","",SUMIFS('Calculator Cost per Bucata'!$W$10:$W$509,'Calculator Cost per Bucata'!$A$10:$A$509,$A20)) | AR20: =IF($A20="","",IF(N($I20)>0,$AQ20/$I20,"")) | AS20: =IF($A20="","",IF(N($H20)>0,$AQ20/$H20,"")) | AT20: =IF($A20="","",IF((N($H20)<=0)+(N($I20)<=0)+($X20=0)+(OR($G20="",$J20="",$K20=""))+(AND($K20="CBM",$AA20=0))+(AND($K20="kg",$Z20=0))+($AL20<>$AM20)=0,"OK",IF(N($H20)<=0,"Lipseste cursul USD. ","")&IF(N($I20)<=0,"Lipseste cursul EUR. ","")&IF($X20=0,"Nicio linie de produs in 'PI Furnizor'. ","")&IF(OR($G20="",$J20="",$K20=""),"Lipseste moneda marfa / moneda transport / baza tarif. ","")&IF(AND($K20="CBM",$AA20=0),"Tarif pe CBM dar lipsesc dimensiunile/volumul. ","")&IF(AND($K20="kg",$Z20=0),"Tarif pe kg dar lipsesc greutatile. ","")&IF($AL20<>$AM20,"Cheia de alocare lipseste - costurile se impart egal pe bucata. ","")))
X21: =IF($A21="","",COUNTIFS('PI Furnizor'!$A$7:$A$506,$A21,'PI Furnizor'!$D$7:$D$506,">0")) | Y21: =IF($A21="","",SUMIFS('PI Furnizor'!$D$7:$D$506,'PI Furnizor'!$A$7:$A$506,$A21)) | Z21: =IF($A21="","",SUMIFS('PI Furnizor'!$O$7:$O$506,'PI Furnizor'!$A$7:$A$506,$A21)) | AA21: =IF($A21="","",SUMIFS('PI Furnizor'!$Q$7:$Q$506,'PI Furnizor'!$A$7:$A$506,$A21)) | AB21: =IF($A21="","",SUMIFS('PI Furnizor'!$N$7:$N$506,'PI Furnizor'!$A$7:$A$506,$A21)) | AC21: =IF($A21="","",$AB21*IF($G21="USD",N($H21),IF($G21="EUR",N($I21),1))) | AD21: =IF($A21="","",IF($N21="Da",$AA21*1000000/$D$5,0)) | AE21: =IF($A21="","",IF($K21="CBM",MAX($AA21,N($M21)),IF($K21="kg",MAX($Z21,IF($N21="Da",$AD21,0),N($M21)),1))) | AF21: =IF($A21="","",IF($K21="Total fix",N($L21),N($L21)*$AE21)+N($O21)) | AG21: =IF($A21="","",$AF21*IF($J21="USD",N($H21),IF($J21="EUR",N($I21),1))) | AH21: =IF($A21="","",IF($Z21>0,$AG21/$Z21,"")) | AI21: =IF($A21="","",IF($AA21>0,$AG21/$AA21,"")) | AJ21: =IF($A21="","",N($P21)*N($Q21)*N($I21)) | AK21: =IF($A21="","",N($R21)*N($S21)) | AL21: =IF($A21="","",IF(OR($W21="",$W21="Automat"),IF($K21="CBM","Volum (CBM)","Greutate"),$W21)) | AM21: =IF($A21="","",IF($AL21="Greutate",IF($Z21>0,"Greutate","Egal pe bucata"),IF($AL21="Volum (CBM)",IF($AA21>0,"Volum (CBM)","Egal pe bucata"),IF($AL21="Valoare marfa",IF($AB21>0,"Valoare marfa","Egal pe bucata"),"Egal pe bucata")))) | AN21: =IF($A21="","",IF($AM21="Greutate",$Z21,IF($AM21="Volum (CBM)",$AA21,IF($AM21="Valoare marfa",$AB21,$Y21)))) | AO21: =IF($A21="","",SUMIFS('Calculator Cost per Bucata'!$V$10:$V$509,'Calculator Cost per Bucata'!$A$10:$A$509,$A21)) | AP21: =IF($A21="","",$AQ21-$AO21) | AQ21: =IF($A21="","",SUMIFS('Calculator Cost per Bucata'!$W$10:$W$509,'Calculator Cost per Bucata'!$A$10:$A$509,$A21)) | AR21: =IF($A21="","",IF(N($I21)>0,$AQ21/$I21,"")) | AS21: =IF($A21="","",IF(N($H21)>0,$AQ21/$H21,"")) | AT21: =IF($A21="","",IF((N($H21)<=0)+(N($I21)<=0)+($X21=0)+(OR($G21="",$J21="",$K21=""))+(AND($K21="CBM",$AA21=0))+(AND($K21="kg",$Z21=0))+($AL21<>$AM21)=0,"OK",IF(N($H21)<=0,"Lipseste cursul USD. ","")&IF(N($I21)<=0,"Lipseste cursul EUR. ","")&IF($X21=0,"Nicio linie de produs in 'PI Furnizor'. ","")&IF(OR($G21="",$J21="",$K21=""),"Lipseste moneda marfa / moneda transport / baza tarif. ","")&IF(AND($K21="CBM",$AA21=0),"Tarif pe CBM dar lipsesc dimensiunile/volumul. ","")&IF(AND($K21="kg",$Z21=0),"Tarif pe kg dar lipsesc greutatile. ","")&IF($AL21<>$AM21,"Cheia de alocare lipseste - costurile se impart egal pe bucata. ","")))
X22: =IF($A22="","",COUNTIFS('PI Furnizor'!$A$7:$A$506,$A22,'PI Furnizor'!$D$7:$D$506,">0")) | Y22: =IF($A22="","",SUMIFS('PI Furnizor'!$D$7:$D$506,'PI Furnizor'!$A$7:$A$506,$A22)) | Z22: =IF($A22="","",SUMIFS('PI Furnizor'!$O$7:$O$506,'PI Furnizor'!$A$7:$A$506,$A22)) | AA22: =IF($A22="","",SUMIFS('PI Furnizor'!$Q$7:$Q$506,'PI Furnizor'!$A$7:$A$506,$A22)) | AB22: =IF($A22="","",SUMIFS('PI Furnizor'!$N$7:$N$506,'PI Furnizor'!$A$7:$A$506,$A22)) | AC22: =IF($A22="","",$AB22*IF($G22="USD",N($H22),IF($G22="EUR",N($I22),1))) | AD22: =IF($A22="","",IF($N22="Da",$AA22*1000000/$D$5,0)) | AE22: =IF($A22="","",IF($K22="CBM",MAX($AA22,N($M22)),IF($K22="kg",MAX($Z22,IF($N22="Da",$AD22,0),N($M22)),1))) | AF22: =IF($A22="","",IF($K22="Total fix",N($L22),N($L22)*$AE22)+N($O22)) | AG22: =IF($A22="","",$AF22*IF($J22="USD",N($H22),IF($J22="EUR",N($I22),1))) | AH22: =IF($A22="","",IF($Z22>0,$AG22/$Z22,"")) | AI22: =IF($A22="","",IF($AA22>0,$AG22/$AA22,"")) | AJ22: =IF($A22="","",N($P22)*N($Q22)*N($I22)) | AK22: =IF($A22="","",N($R22)*N($S22)) | AL22: =IF($A22="","",IF(OR($W22="",$W22="Automat"),IF($K22="CBM","Volum (CBM)","Greutate"),$W22)) | AM22: =IF($A22="","",IF($AL22="Greutate",IF($Z22>0,"Greutate","Egal pe bucata"),IF($AL22="Volum (CBM)",IF($AA22>0,"Volum (CBM)","Egal pe bucata"),IF($AL22="Valoare marfa",IF($AB22>0,"Valoare marfa","Egal pe bucata"),"Egal pe bucata")))) | AN22: =IF($A22="","",IF($AM22="Greutate",$Z22,IF($AM22="Volum (CBM)",$AA22,IF($AM22="Valoare marfa",$AB22,$Y22)))) | AO22: =IF($A22="","",SUMIFS('Calculator Cost per Bucata'!$V$10:$V$509,'Calculator Cost per Bucata'!$A$10:$A$509,$A22)) | AP22: =IF($A22="","",$AQ22-$AO22) | AQ22: =IF($A22="","",SUMIFS('Calculator Cost per Bucata'!$W$10:$W$509,'Calculator Cost per Bucata'!$A$10:$A$509,$A22)) | AR22: =IF($A22="","",IF(N($I22)>0,$AQ22/$I22,"")) | AS22: =IF($A22="","",IF(N($H22)>0,$AQ22/$H22,"")) | AT22: =IF($A22="","",IF((N($H22)<=0)+(N($I22)<=0)+($X22=0)+(OR($G22="",$J22="",$K22=""))+(AND($K22="CBM",$AA22=0))+(AND($K22="kg",$Z22=0))+($AL22<>$AM22)=0,"OK",IF(N($H22)<=0,"Lipseste cursul USD. ","")&IF(N($I22)<=0,"Lipseste cursul EUR. ","")&IF($X22=0,"Nicio linie de produs in 'PI Furnizor'. ","")&IF(OR($G22="",$J22="",$K22=""),"Lipseste moneda marfa / moneda transport / baza tarif. ","")&IF(AND($K22="CBM",$AA22=0),"Tarif pe CBM dar lipsesc dimensiunile/volumul. ","")&IF(AND($K22="kg",$Z22=0),"Tarif pe kg dar lipsesc greutatile. ","")&IF($AL22<>$AM22,"Cheia de alocare lipseste - costurile se impart egal pe bucata. ","")))
... X108: =IF($A108="","",COUNTIFS('PI Furnizor'!$A$7:$A$506,$A108,'PI Furnizor'!$D$7:$D$506,">0")) | Y108: =IF($A108="","",SUMIFS('PI Furnizor'!$D$7:$D$506,'PI Furnizor'!$A$7:$A$506,$A108)) | Z108: =IF($A108="","",SUMIFS('PI Furnizor'!$O$7:$O$506,'PI Furnizor'!$A$7:$A$506,$A108)) | AA108: =IF($A108="","",SUMIFS('PI Furnizor'!$Q$7:$Q$506,'PI Furnizor'!$A$7:$A$506,$A108)) | AB108: =IF($A108="","",SUMIFS('PI Furnizor'!$N$7:$N$506,'PI Furnizor'!$A$7:$A$506,$A108)) | AC108: =IF($A108="","",$AB108*IF($G108="USD",N($H108),IF($G108="EUR",N($I108),1))) | AD108: =IF($A108="","",IF($N108="Da",$AA108*1000000/$D$5,0)) | AE108: =IF($A108="","",IF($K108="CBM",MAX($AA108,N($M108)),IF($K108="kg",MAX($Z108,IF($N108="Da",$AD108,0),N($M108)),1))) | AF108: =IF($A108="","",IF($K108="Total fix",N($L108),N($L108)*$AE108)+N($O108)) | AG108: =IF($A108="","",$AF108*IF($J108="USD",N($H108),IF($J108="EUR",N($I108),1))) | AH108: =IF($A108="","",IF($Z108>0,$AG108/$Z108,"")) | AI108: =IF($A108="","",IF($AA108>0,$AG108/$AA108,"")) | AJ108: =IF($A108="","",N($P108)*N($Q108)*N($I108)) | AK108: =IF($A108="","",N($R108)*N($S108)) | AL108: =IF($A108="","",IF(OR($W108="",$W108="Automat"),IF($K108="CBM","Volum (CBM)","Greutate"),$W108)) | AM108: =IF($A108="","",IF($AL108="Greutate",IF($Z108>0,"Greutate","Egal pe bucata"),IF($AL108="Volum (CBM)",IF($AA108>0,"Volum (CBM)","Egal pe bucata"),IF($AL108="Valoare marfa",IF($AB108>0,"Valoare marfa","Egal pe bucata"),"Egal pe bucata")))) | AN108: =IF($A108="","",IF($AM108="Greutate",$Z108,IF($AM108="Volum (CBM)",$AA108,IF($AM108="Valoare marfa",$AB108,$Y108)))) | AO108: =IF($A108="","",SUMIFS('Calculator Cost per Bucata'!$V$10:$V$509,'Calculator Cost per Bucata'!$A$10:$A$509,$A108)) | AP108: =IF($A108="","",$AQ108-$AO108) | AQ108: =IF($A108="","",SUMIFS('Calculator Cost per Bucata'!$W$10:$W$509,'Calculator Cost per Bucata'!$A$10:$A$509,$A108)) | AR108: =IF($A108="","",IF(N($I108)>0,$AQ108/$I108,"")) | AS108: =IF($A108="","",IF(N($H108)>0,$AQ108/$H108,"")) | AT108: =IF($A108="","",IF((N($H108)<=0)+(N($I108)<=0)+($X108=0)+(OR($G108="",$J108="",$K108=""))+(AND($K108="CBM",$AA108=0))+(AND($K108="kg",$Z108=0))+($AL108<>$AM108)=0,"OK",IF(N($H108)<=0,"Lipseste cursul USD. ","")&IF(N($I108)<=0,"Lipseste cursul EUR. ","")&IF($X108=0,"Nicio linie de produs in 'PI Furnizor'. ","")&IF(OR($G108="",$J108="",$K108=""),"Lipseste moneda marfa / moneda transport / baza tarif. ","")&IF(AND($K108="CBM",$AA108=0),"Tarif pe CBM dar lipsesc dimensiunile/volumul. ","")&IF(AND($K108="kg",$Z108=0),"Tarif pe kg dar lipsesc greutatile. ","")&IF($AL108<>$AM108,"Cheia de alocare lipseste - costurile se impart egal pe bucata. ","")))

Sheet Calculator Cost per Bucata
A1: COST REAL PER BUCATA - LA INTRAREA IN TARA (toate comenzile)
A3: Tabelul se completeaza singur din 'PI Furnizor' + 'Comenzi' - fiecare produs foloseste data/cursul/transportul comenzii lui. Transportul si taxele fixe pe comanda se impart pe bucata dupa metoda aleasa la comanda (greutate, CBM, egal, valoare). Baza TVA = valoare in vama CIF (marfa + transport + asigurare) + taxe vamale; taxa logistica RO si comisioanele de broker NU intra in baza TVA. Foloseste filtrul de pe coloana 'Nr. comanda' pentru o singura comanda - totalurile din rand 5 se recalculeaza dupa filtru.
A5: TOTAL randuri afisate (se actualizeaza cu filtrul) | E5: =SUBTOTAL(109,E10:E509) -> 9 | S5: TVA total: | T5: =W5-V5 -> 163.21965 | V5: =SUBTOTAL(109,V10:V509) -> 777.23642 | W5: =SUBTOTAL(109,W10:W509) -> 940.45607
A8: IDENTIFICARE | G8: PRET MARFA | I8: ALOCARE TRANSPORT | K8: VALOARE IN VAMA, TAXE, TVA (pe bucata) | P8: COST FINAL fara TVA /buc (recuperabil) | S8: COST FINAL cu TVA /buc (cash) | V8: TOTAL LINIE (RON) | X8: TEHNIC (nu modifica)
A9: Nr. comanda | B9: Data comanda | C9: Item Number | D9: Descriere | E9: Cantitate (buc) | F9: Moneda marfa | G9: Pret produs /buc (moneda marfa) | H9: Pret produs /buc (RON) | I9: Cota alocare transport + taxe fixe (%) | J9: Transport + asigurare /buc (RON) | K9: Valoare in vama (CIF) /buc (RON) | L9: Taxa vamala /buc (RON) | M9: Baza TVA import /buc (RON) | N9: TVA import /buc (RON) | O9: Taxa logistica RO + broker/local /buc (RON) | P9: RON | Q9: EUR | R9: USD | S9: RON | T9: EUR | U9: USD | V9: Fara TVA (RON) | W9: Cu TVA (RON) | X9: Rand in Comenzi | Y9: Valid (1/0) | Z9: Status | AA9: Curs USD | AB9: Curs EUR | AC9: Cota TVA | AD9: Taxa vamala % | AE9: Cheie alocare
A10: =IF(COUNTA(INDEX('PI Furnizor'!$A:$E,ROW()-3,0))=0,"",IF(INDEX('PI Furnizor'!$A:$A,ROW()-3)="","?",INDEX('PI Furnizor'!$A:$A,ROW()-3))) -> C001 | B10: =IF(ISNUMBER($X10),INDEX(Comenzi!$B:$B,$X10),"") -> 46260 | C10: =IF($A10="","",INDEX('PI Furnizor'!$B:$B,ROW()-3)&"") -> 8821-DS | D10: =IF($A10="","",INDEX('PI Furnizor'!$C:$C,ROW()-3)&"") -> Christmas flower | E10: =IF($A10="","",N(INDEX('PI Furnizor'!$D:$D,ROW()-3))) -> 1 | F10: =IF(ISNUMBER($X10),INDEX(Comenzi!$G:$G,$X10),"") -> USD | G10: =IF($A10="","",N(INDEX('PI Furnizor'!$E:$E,ROW()-3))) -> 6.15 | H10: =IF($Y10<>1,"",$G10*IF($F10="USD",$AA10,IF($F10="EUR",$AB10,1))) -> 29.12886 | I10: =IF($Y10<>1,"",IFERROR($AE10/INDEX(Comenzi!$AN:$AN,$X10),0)) -> 0.11133603 | J10: =IF($Y10<>1,"",INDEX(Comenzi!$AG:$AG,$X10)*$I10/$E10) -> 35.900761 | K10: =IF($Y10<>1,"",$H10+$J10) -> 65.029621 | L10: =IF($Y10<>1,"",$K10*$AD10+INDEX(Comenzi!$AJ:$AJ,$X10)*$I10/$E10) -> 0 | M10: =IF($Y10<>1,"",$K10+$L10) -> 65.029621 | N10: =IF($Y10<>1,"",$M10*$AC10) -> 13.656221 | O10: =IF($Y10<>1,"",(INDEX(Comenzi!$AK:$AK,$X10)+N(INDEX(Comenzi!$T:$T,$X10)))*$I10/$E10) -> 0 | P10: =IF($Y10<>1,"",$M10+$O10) -> 65.029621 | Q10: =IF($Y10<>1,"",$P10/$AB10) -> 12.190616 | R10: =IF($Y10<>1,"",$P10/$AA10) -> 13.729757 | S10: =IF($Y10<>1,"",$P10+$N10) -> 78.685842 | T10: =IF($Y10<>1,"",$S10/$AB10) -> 14.750645 | U10: =IF($Y10<>1,"",$S10/$AA10) -> 16.613006 | V10: =IF($Y10<>1,"",$P10*$E10) -> 65.029621 | W10: =IF($Y10<>1,"",$S10*$E10) -> 78.685842 | X10: =IF($A10="","",IFERROR(MATCH($A10,Comenzi!$A$9:$A$108,0)+8,"")) -> 9 | Y10: =IF($A10="","",IF(AND(ISNUMBER($X10),N($E10)>0,N($AA10)>0,N($AB10)>0,OR($F10="USD",$F10="EUR",$F10="RON")),1,0)) -> 1 | Z10: =IF($A10="","",IF($A10="?","Lipseste ID-ul comenzii (col. A din PI Furnizor)",IF(NOT(ISNUMBER($X10)),"ID comanda negasit in foaia Comenzi",IF(N($E10)<=0,"Lipseste cantitatea",IF(N($G10)=0,"Pret unitar lipsa",IF($Y10<>1,"Curs sau moneda marfa lipsa (foaia Comenzi)",IF(INDEX(Comenzi!$AT:$AT,$X10)<>"OK","Avertisment comanda: "&INDEX(Comenzi!$AT:$AT,$X10),"OK"))))))) -> OK | AA10: =IF(ISNUMBER($X10),INDEX(Comenzi!$H:$H,$X10),"") -> 4.7364 | AB10: =IF(ISNUMBER($X10),INDEX(Comenzi!$I:$I,$X10),"") -> 5.3344 | AC10: =IF(ISNUMBER($X10),IF(INDEX(Comenzi!$V:$V,$X10)="",Comenzi!$D$3,INDEX(Comenzi!$V:$V,$X10)),"") -> 0.21 | AD10: =IF(ISNUMBER($X10),IF(INDEX(Comenzi!$U:$U,$X10)="",Comenzi!$D$4,INDEX(Comenzi!$U:$U,$X10)),"") -> 0 | AE10: =IF($Y10<>1,"",IF(INDEX(Comenzi!$AM:$AM,$X10)="Greutate",INDEX('PI Furnizor'!$O:$O,ROW()-3),IF(INDEX(Comenzi!$AM:$AM,$X10)="Volum (CBM)",INDEX('PI Furnizor'!$Q:$Q,ROW()-3),IF(INDEX(Comenzi!$AM:$AM,$X10)="Valoare marfa",INDEX('PI Furnizor'!$N:$N,ROW()-3),$E10)))) -> 0.55
A11: =IF(COUNTA(INDEX('PI Furnizor'!$A:$E,ROW()-3,0))=0,"",IF(INDEX('PI Furnizor'!$A:$A,ROW()-3)="","?",INDEX('PI Furnizor'!$A:$A,ROW()-3))) -> C001 | B11: =IF(ISNUMBER($X11),INDEX(Comenzi!$B:$B,$X11),"") -> 46260 | C11: =IF($A11="","",INDEX('PI Furnizor'!$B:$B,ROW()-3)&"") -> 11153-DS | D11: =IF($A11="","",INDEX('PI Furnizor'!$C:$C,ROW()-3)&"") -> Garland | E11: =IF($A11="","",N(INDEX('PI Furnizor'!$D:$D,ROW()-3))) -> 1 | F11: =IF(ISNUMBER($X11),INDEX(Comenzi!$G:$G,$X11),"") -> USD | G11: =IF($A11="","",N(INDEX('PI Furnizor'!$E:$E,ROW()-3))) -> 5.51 | H11: =IF($Y11<>1,"",$G11*IF($F11="USD",$AA11,IF($F11="EUR",$AB11,1))) -> 26.097564 | I11: =IF($Y11<>1,"",IFERROR($AE11/INDEX(Comenzi!$AN:$AN,$X11),0)) -> 0.087044534 | J11: =IF($Y11<>1,"",INDEX(Comenzi!$AG:$AG,$X11)*$I11/$E11) -> 28.067868 | K11: =IF($Y11<>1,"",$H11+$J11) -> 54.165432 | L11: =IF($Y11<>1,"",$K11*$AD11+INDEX(Comenzi!$AJ:$AJ,$X11)*$I11/$E11) -> 0 | M11: =IF($Y11<>1,"",$K11+$L11) -> 54.165432 | N11: =IF($Y11<>1,"",$M11*$AC11) -> 11.374741 | O11: =IF($Y11<>1,"",(INDEX(Comenzi!$AK:$AK,$X11)+N(INDEX(Comenzi!$T:$T,$X11)))*$I11/$E11) -> 0 | P11: =IF($Y11<>1,"",$M11+$O11) -> 54.165432 | Q11: =IF($Y11<>1,"",$P11/$AB11) -> 10.153988 | R11: =IF($Y11<>1,"",$P11/$AA11) -> 11.435992 | S11: =IF($Y11<>1,"",$P11+$N11) -> 65.540173 | T11: =IF($Y11<>1,"",$S11/$AB11) -> 12.286325 | U11: =IF($Y11<>1,"",$S11/$AA11) -> 13.83755 | V11: =IF($Y11<>1,"",$P11*$E11) -> 54.165432 | W11: =IF($Y11<>1,"",$S11*$E11) -> 65.540173 | X11: =IF($A11="","",IFERROR(MATCH($A11,Comenzi!$A$9:$A$108,0)+8,"")) -> 9 | Y11: =IF($A11="","",IF(AND(ISNUMBER($X11),N($E11)>0,N($AA11)>0,N($AB11)>0,OR($F11="USD",$F11="EUR",$F11="RON")),1,0)) -> 1 | Z11: =IF($A11="","",IF($A11="?","Lipseste ID-ul comenzii (col. A din PI Furnizor)",IF(NOT(ISNUMBER($X11)),"ID comanda negasit in foaia Comenzi",IF(N($E11)<=0,"Lipseste cantitatea",IF(N($G11)=0,"Pret unitar lipsa",IF($Y11<>1,"Curs sau moneda marfa lipsa (foaia Comenzi)",IF(INDEX(Comenzi!$AT:$AT,$X11)<>"OK","Avertisment comanda: "&INDEX(Comenzi!$AT:$AT,$X11),"OK"))))))) -> OK | AA11: =IF(ISNUMBER($X11),INDEX(Comenzi!$H:$H,$X11),"") -> 4.7364 | AB11: =IF(ISNUMBER($X11),INDEX(Comenzi!$I:$I,$X11),"") -> 5.3344 | AC11: =IF(ISNUMBER($X11),IF(INDEX(Comenzi!$V:$V,$X11)="",Comenzi!$D$3,INDEX(Comenzi!$V:$V,$X11)),"") -> 0.21 | AD11: =IF(ISNUMBER($X11),IF(INDEX(Comenzi!$U:$U,$X11)="",Comenzi!$D$4,INDEX(Comenzi!$U:$U,$X11)),"") -> 0 | AE11: =IF($Y11<>1,"",IF(INDEX(Comenzi!$AM:$AM,$X11)="Greutate",INDEX('PI Furnizor'!$O:$O,ROW()-3),IF(INDEX(Comenzi!$AM:$AM,$X11)="Volum (CBM)",INDEX('PI Furnizor'!$Q:$Q,ROW()-3),IF(INDEX(Comenzi!$AM:$AM,$X11)="Valoare marfa",INDEX('PI Furnizor'!$N:$N,ROW()-3),$E11)))) -> 0.43
A12: =IF(COUNTA(INDEX('PI Furnizor'!$A:$E,ROW()-3,0))=0,"",IF(INDEX('PI Furnizor'!$A:$A,ROW()-3)="","?",INDEX('PI Furnizor'!$A:$A,ROW()-3))) -> C001 | B12: =IF(ISNUMBER($X12),INDEX(Comenzi!$B:$B,$X12),"") -> 46260 | C12: =IF($A12="","",INDEX('PI Furnizor'!$B:$B,ROW()-3)&"") -> C0230 | D12: =IF($A12="","",INDEX('PI Furnizor'!$C:$C,ROW()-3)&"") -> EC-Fairy Land-Castle | E12: =IF($A12="","",N(INDEX('PI Furnizor'!$D:$D,ROW()-3))) -> 1 | F12: =IF(ISNUMBER($X12),INDEX(Comenzi!$G:$G,$X12),"") -> USD | G12: =IF($A12="","",N(INDEX('PI Furnizor'!$E:$E,ROW()-3))) -> 4.23 | H12: =IF($Y12<>1,"",$G12*IF($F12="USD",$AA12,IF($F12="EUR",$AB12,1))) -> 20.034972 | I12: =IF($Y12<>1,"",IFERROR($AE12/INDEX(Comenzi!$AN:$AN,$X12),0)) -> 0.16194332 | J12: =IF($Y12<>1,"",INDEX(Comenzi!$AG:$AG,$X12)*$I12/$E12) -> 52.219289 | K12: =IF($Y12<>1,"",$H12+$J12) -> 72.254261 | L12: =IF($Y12<>1,"",$K12*$AD12+INDEX(Comenzi!$AJ:$AJ,$X12)*$I12/$E12) -> 0 | M12: =IF($Y12<>1,"",$K12+$L12) -> 72.254261 | N12: =IF($Y12<>1,"",$M12*$AC12) -> 15.173395 | O12: =IF($Y12<>1,"",(INDEX(Comenzi!$AK:$AK,$X12)+N(INDEX(Comenzi!$T:$T,$X12)))*$I12/$E12) -> 0 | P12: =IF($Y12<>1,"",$M12+$O12) -> 72.254261 | Q12: =IF($Y12<>1,"",$P12/$AB12) -> 13.544965 | R12: =IF($Y12<>1,"",$P12/$AA12) -> 15.255101 | S12: =IF($Y12<>1,"",$P12+$N12) -> 87.427656 | T12: =IF($Y12<>1,"",$S12/$AB12) -> 16.389408 | U12: =IF($Y12<>1,"",$S12/$AA12) -> 18.458672 | V12: =IF($Y12<>1,"",$P12*$E12) -> 72.254261 | W12: =IF($Y12<>1,"",$S12*$E12) -> 87.427656 | X12: =IF($A12="","",IFERROR(MATCH($A12,Comenzi!$A$9:$A$108,0)+8,"")) -> 9 | Y12: =IF($A12="","",IF(AND(ISNUMBER($X12),N($E12)>0,N($AA12)>0,N($AB12)>0,OR($F12="USD",$F12="EUR",$F12="RON")),1,0)) -> 1 | Z12: =IF($A12="","",IF($A12="?","Lipseste ID-ul comenzii (col. A din PI Furnizor)",IF(NOT(ISNUMBER($X12)),"ID comanda negasit in foaia Comenzi",IF(N($E12)<=0,"Lipseste cantitatea",IF(N($G12)=0,"Pret unitar lipsa",IF($Y12<>1,"Curs sau moneda marfa lipsa (foaia Comenzi)",IF(INDEX(Comenzi!$AT:$AT,$X12)<>"OK","Avertisment comanda: "&INDEX(Comenzi!$AT:$AT,$X12),"OK"))))))) -> OK | AA12: =IF(ISNUMBER($X12),INDEX(Comenzi!$H:$H,$X12),"") -> 4.7364 | AB12: =IF(ISNUMBER($X12),INDEX(Comenzi!$I:$I,$X12),"") -> 5.3344 | AC12: =IF(ISNUMBER($X12),IF(INDEX(Comenzi!$V:$V,$X12)="",Comenzi!$D$3,INDEX(Comenzi!$V:$V,$X12)),"") -> 0.21 | AD12: =IF(ISNUMBER($X12),IF(INDEX(Comenzi!$U:$U,$X12)="",Comenzi!$D$4,INDEX(Comenzi!$U:$U,$X12)),"") -> 0 | AE12: =IF($Y12<>1,"",IF(INDEX(Comenzi!$AM:$AM,$X12)="Greutate",INDEX('PI Furnizor'!$O:$O,ROW()-3),IF(INDEX(Comenzi!$AM:$AM,$X12)="Volum (CBM)",INDEX('PI Furnizor'!$Q:$Q,ROW()-3),IF(INDEX(Comenzi!$AM:$AM,$X12)="Valoare marfa",INDEX('PI Furnizor'!$N:$N,ROW()-3),$E12)))) -> 0.8
